{"errorMessage": "An error occurred (AccessDenied) when calling the ListObjectsV2 operation: User: arn:aws:sts::116981788394:assumed-role/LambdaStack-SizeTrackingLambdaServiceRoleEE707D62-zSUzsQyd6LXi/LambdaStack-SizeTrackingLambda9C763A26-DD0AjDRUxt6B is not authorized to perform: s3:ListBucket on resource: \"arn:aws:s3:::testbucket-lu-6620ass2\" because no identity-based policy allows the s3:ListBucket action", "errorType": "ClientError", "requestId": "73df5635-747a-4e2a-bbe4-2f366a1e7231", "stackTrace": ["  File \"/var/task/lambda_function.py\", line 25, in lambda_handler\n    total_size, total_objects = get_s3_bucket_size()\n", "  File \"/var/task/lambda_function.py\", line 16, in get_s3_bucket_size\n    for page in paginator.paginate(Bucket=BUCKET_NAME):\n", "  File \"/var/runtime/botocore/paginate.py\", line 269, in __iter__\n    response = self._make_request(current_kwargs)\n", "  File \"/var/runtime/botocore/paginate.py\", line 357, in _make_request\n    return self._method(**current_kwargs)\n", "  File \"/var/runtime/botocore/client.py\", line 569, in _api_call\n    return self._make_api_call(operation_name, kwargs)\n", "  File \"/var/runtime/botocore/client.py\", line 1023, in _make_api_call\n    raise error_class(parsed_response, operation_name)\n"]}